// 事实上throw语句可以将任意对象作为错误抛出并由try...catch语句来捕获
try {
  throw 1;
}
catch (e) {
  console.log(1);
}
